Loaded dependency [python3/3.10.7]: gcc/11.3.0-binutils-2.38
Loaded module: python3/3.10.7

Loading python3/3.10.7
  Loading requirement: gcc/11.3.0-binutils-2.38
Loaded module: cuda/11.5
Loaded module: cudnn/v8.3.2.44-prod-cuda-11.5
Loaded module: ffmpeg/5.0.1
Traceback (most recent call last):
  File "/zhome/2b/d/156632/Desktop/bachelor/Vision_model/bach/lib/python3.10/site-packages/torch/utils/data/dataloader.py", line 1120, in _try_get_data
    data = self._data_queue.get(timeout=timeout)
  File "/appl/python/3.10.7/lib/python3.10/multiprocessing/queues.py", line 113, in get
    if not self._poll(timeout):
  File "/appl/python/3.10.7/lib/python3.10/multiprocessing/connection.py", line 262, in poll
    return self._poll(timeout)
  File "/appl/python/3.10.7/lib/python3.10/multiprocessing/connection.py", line 429, in _poll
    r = wait([self], timeout)
  File "/appl/python/3.10.7/lib/python3.10/multiprocessing/connection.py", line 936, in wait
    ready = selector.select(timeout)
  File "/appl/python/3.10.7/lib/python3.10/selectors.py", line 416, in select
    fd_event_list = self._selector.poll(timeout)
  File "/zhome/2b/d/156632/Desktop/bachelor/Vision_model/bach/lib/python3.10/site-packages/torch/utils/data/_utils/signal_handling.py", line 66, in handler
    _error_if_any_worker_fails()
RuntimeError: DataLoader worker (pid 150353) is killed by signal: Killed. 

The above exception was the direct cause of the following exception:

Traceback (most recent call last):
  File "/zhome/2b/d/156632/Desktop/bachelor/Vision_model/main.py", line 225, in <module>
    main()
  File "/zhome/2b/d/156632/Desktop/bachelor/Vision_model/main.py", line 122, in main
    train_loss = train(model, dataloaderTrain, optimizer, criterion, CFG)
  File "/zhome/2b/d/156632/Desktop/bachelor/Vision_model/main.py", line 148, in train
    for i, (ipt, trg) in enumerate(dataloader):
  File "/zhome/2b/d/156632/Desktop/bachelor/Vision_model/bach/lib/python3.10/site-packages/torch/utils/data/dataloader.py", line 628, in __next__
    data = self._next_data()
  File "/zhome/2b/d/156632/Desktop/bachelor/Vision_model/bach/lib/python3.10/site-packages/torch/utils/data/dataloader.py", line 1316, in _next_data
    idx, data = self._get_data()
  File "/zhome/2b/d/156632/Desktop/bachelor/Vision_model/bach/lib/python3.10/site-packages/torch/utils/data/dataloader.py", line 1282, in _get_data
    success, data = self._try_get_data()
  File "/zhome/2b/d/156632/Desktop/bachelor/Vision_model/bach/lib/python3.10/site-packages/torch/utils/data/dataloader.py", line 1133, in _try_get_data
    raise RuntimeError('DataLoader worker (pid(s) {}) exited unexpectedly'.format(pids_str)) from e
RuntimeError: DataLoader worker (pid(s) 150353) exited unexpectedly
